<?xml version='1.0'?>

<robot xmlns:xacro="http://www.ros.org/wiki/xacro">

    <xacro:macro name="nova_right" params="parent prefix">

        <!-- Constants -->
        <xacro:property name="PI"           value="3.1415926535897931"/>
        <xacro:property name="hover_height" value="0.5"/>
        <xacro:property name="color_blue"   value="0.0 0.0 1.0 1.0"/> 

        <link name="r_glove_hub">
            <visual name="r_glove_hub_visual">
                <origin xyz="0.04999999711722506 0.0384999985617558 0.01800000348079321" rpy="1.570796326794895 2.487149296841506e-15 -1.0232564774448725e-15" />
                <geometry>
                    <mesh filename="package://senseglove_description/meshes/nova/glove_hub.stl" scale="0.001 0.001 0.001" />
                </geometry>
                <material name="Blue">
                    <color rgba="${color_blue}"/>
                </material>
            </visual>
        </link>

        <link name="r_thumb_brake">
            <visual name="r_thumb_brake_visual">
                <origin xyz="-0.018915103190668782 -0.05603821597043106 0.01899999971512907" rpy="-1.5707963267948946 -7.90166543307436e-16 2.3561944901923444" />
                <geometry>
                    <mesh filename="package://senseglove_description/meshes/nova/thumb_brake.stl" scale="0.001 0.001 0.001" />
                </geometry>
            </visual>
        </link>

        <link name="r_thumb_flexion_one">
            <visual name="r_thumb_flexion_one_visual">
                <origin xyz="0.06136539170263021 -0.025453226250843307 -0.00892943928989283" rpy="1.4833638815934393 -0.08710016207930293 1.5727025747130363" />
                <geometry>
                    <mesh filename="package://senseglove_description/meshes/nova/thumb_flexion_one.stl" scale="0.001 0.001 0.001" />
                </geometry>
            </visual>
        </link>

        <link name="r_thumb_flexion_two">
            <visual name="r_thumb_flexion_two_visual">
                <origin xyz="0.06136538618020733 -0.025453232684174015 -0.00892943224376902" rpy="1.483363881593886 -0.08710016207836464 1.5727025747122354" />
                <geometry>
                    <mesh filename="package://senseglove_description/meshes/nova/thumb_flexion_two.stl" scale="0.001 0.001 0.001" />
                </geometry>
            </visual>
        </link>

        <link name="r_thumb_flexion_three">
            <visual name="r_thumb_flexion_three_visual">
                <origin xyz="0.06136539065790094 -0.025453229117376783 -0.008929435197658486" rpy="1.483363881593889 -0.08710016207859443 1.5727025747130292" />
                <geometry>
                    <mesh filename="package://senseglove_description/meshes/nova/thumb_flexion_three.stl" scale="0.001 0.001 0.001" />
                </geometry>
            </visual>
        </link>

        <link name="r_index_brake">
            <visual name="r_index_brake_visual">
                <origin xyz="-0.0262500029572806 -0.053000001438244 -0.0069999981186812344" rpy="1.570796326794896 2.6489608621219915e-15 -1.5925779067116534e-15" />
                <geometry>
                    <mesh filename="package://senseglove_description/meshes/nova/index_brake.stl" scale="0.001 0.001 0.001" />
                </geometry>
            </visual>
        </link>

        <link name="r_index_flexion_one">
            <visual name="r_index_flexion_one_visual">
                <origin xyz="0.06050000143824393 0.012000001881318724 -0.026249997042719412" rpy="-3.1415926535897927 -1.5707963267948912 0" />
                <geometry>
                    <mesh filename="package://senseglove_description/meshes/nova/index_flexion_one.stl" scale="0.001 0.001 0.001" />
                </geometry>
            </visual>
        </link>

        <link name="r_index_flexion_two">
            <visual name="r_index_flexion_two_visual">
                <origin xyz="0.060500001438244216 0.011999998118680907 -0.026250002957280274" rpy="3.141592653589791 -1.5707963267948903 0" />
                <geometry>
                    <mesh filename="package://senseglove_description/meshes/nova/index_flexion_two.stl" scale="0.001 0.001 0.001" />
                </geometry>
            </visual>
        </link>

        <link name="r_index_flexion_three">
            <visual name="r_index_flexion_three_visual">
                <origin xyz="0.06050000143824457 -0.011999998118681328 0.026250002957280093" rpy="-2.8085173076064534e-15 1.5707963267948908 0" />
                <geometry>
                    <mesh filename="package://senseglove_description/meshes/nova/index_flexion_three.stl" scale="0.001 0.001 0.001" />
                </geometry>
            </visual>
        </link>

        <link name="r_middle_brake">
            <visual name="r_middle_brake_visual">
                <origin xyz="-0.026250002957280583 -0.05300000143824441 -0.006999996519206939" rpy="1.5707963267948946 2.1250764796468657e-15 -8.522785545269755e-16" />
                <geometry>
                    <mesh filename="package://senseglove_description/meshes/nova/middle_brake.stl" scale="0.001 0.001 0.001" />
                </geometry>
            </visual>
        </link>

        <link name="r_middle_flexion_one">
            <visual name="r_middle_flexion_one_visual">
                <origin xyz="0.06050000143824513 -0.011999996519206886 0.026250002957280607" rpy="-2.142383492831341e-15 1.570796326794891 0" />
                <geometry>
                    <mesh filename="package://senseglove_description/meshes/nova/middle_flexion_one.stl" scale="0.001 0.001 0.001" />
                </geometry>
            </visual>
        </link>

        <link name="r_middle_flexion_two">
            <visual name="r_middle_flexion_two_visual">
                <origin xyz="0.06050000143824574 -0.011999996519206926 0.02625000295728071" rpy="-5.2232523861661165e-15 1.570796326794891 0" />
                <geometry>
                    <mesh filename="package://senseglove_description/meshes/nova/middle_flexion_two.stl" scale="0.001 0.001 0.001" />
                </geometry>
            </visual>
        </link>

        <link name="r_middle_flexion_three">
            <visual name="r_middle_flexion_three_visual">
                <origin xyz="0.06050000143824516 -0.011999996519207294 0.026250002957280704" rpy="-5.264885749589545e-15 1.5707963267948906 0" />
                <geometry>
                    <mesh filename="package://senseglove_description/meshes/nova/middle_flexion_three.stl" scale="0.001 0.001 0.001" />
                </geometry>
            </visual>
        </link>

        <link name="r_ring_brake">
            <visual name="r_ring_brake_visual">
                <origin xyz="-0.026250002957280572 -0.05300000143824431 -0.006999996519206952" rpy="1.5707963267948946 2.4282221493532045e-15 -1.315938020877693e-15" />
                <geometry>
                    <mesh filename="package://senseglove_description/meshes/nova/ring_brake.stl" scale="0.001 0.001 0.001" />
                </geometry>
            </visual>
        </link>

        <link name="r_ring_flexion_one">
            <visual name="r_ring_flexion_one_visual">
                <origin xyz="0.06050000143824468 -0.011999996519206753 0.02625000295728042" rpy="-3.807718029769072e-15 1.5707963267948912 0" />
                <geometry>
                    <mesh filename="package://senseglove_description/meshes/nova/ring_flexion_one.stl" scale="0.001 0.001 0.001" />
                </geometry>
            </visual>
        </link>

        <link name="r_ring_flexion_two">
            <visual name="r_ring_flexion_two_visual">
                <origin xyz="0.060500001438245035 -0.011999996519206921 0.026250002957280714" rpy="-4.543240783583241e-15 1.5707963267948915 0" />
                <geometry>
                    <mesh filename="package://senseglove_description/meshes/nova/ring_flexion_two.stl" scale="0.001 0.001 0.001" />
                </geometry>
            </visual>
        </link>

        <link name="r_ring_flexion_three">
            <visual name="r_ring_flexion_three_visual">
                <origin xyz="0.060500001438244945 -0.01199999651920702 0.02625000295728051" rpy="-5.806119474094289e-15 1.5707963267948877 0" />
                <geometry>
                    <mesh filename="package://senseglove_description/meshes/nova/ring_flexion_three.stl" scale="0.001 0.001 0.001" />
                </geometry>
            </visual>
        </link>

        <link name="r_pinky_brake">
            <visual name="r_pinky_brake_visual">
                <origin xyz="0.026249997117225074 -0.05300000064848244 0.015000003480793117" rpy="-1.5707963267948948 -9.609279519332261e-16 -3.141592653589791" />
                <geometry>
                    <mesh filename="package://senseglove_description/meshes/nova/pinky_brake.stl" scale="0.001 0.001 0.001" />
                </geometry>
            </visual>
        </link>

        <link name="r_pinky_flexion_one">
            <visual name="r_pinky_flexion_one_visual">
                <origin xyz="0.060500000648481794 -0.012000003480793438 0.02624999711722504" rpy="9.284446810305057e-15 1.5707963267948926 0" />
                <geometry>
                    <mesh filename="package://senseglove_description/meshes/nova/pinky_flexion_one.stl" scale="0.001 0.001 0.001" />
                </geometry>
            </visual>
        </link>

        <link name="r_pinky_flexion_two">
            <visual name="r_pinky_flexion_two_visual">
                <origin xyz="0.06050000064848222 -0.012000003480793029 0.026249997117225022" rpy="7.896668029523656e-15 1.5707963267948934 0" />
                <geometry>
                    <mesh filename="package://senseglove_description/meshes/nova/pinky_flexion_two.stl" scale="0.001 0.001 0.001" />
                </geometry>
            </visual>
        </link>

        <link name="r_pinky_flexion_three">
            <visual name="r_pinky_flexion_three_visual">
                <origin xyz="0.060500000648482946 -0.01200000348079279 0.026249997117224862" rpy="8.201598196469284e-15 1.5707963267948941 0" />
                <geometry>
                    <mesh filename="package://senseglove_description/meshes/nova/pinky_flexion_three.stl" scale="0.001 0.001 0.001" />
                </geometry>
            </visual>
        </link>

        <link name="r_thumper">
            <visual name="r_thumper_visual">
                <origin xyz="-2.882775058665743e-09 -1.4382443502825026e-09 3.4807930182623183e-09" rpy="1.570796326794894 -5.43408119385757e-15 -1.4163819959694949e-15" />
                <geometry>
                    <mesh filename="package://senseglove_description/meshes/nova/thumper.stl" scale="0.001 0.001 0.001" />
                </geometry>
            </visual>
        </link>

        <!-- Joints -->
        <joint name="joint_base_fixed_parent_joint" type="fixed">
            <parent link="${parent}"/>
            <child link="r_glove_hub"/>
            <origin xyz="0.5 0 ${hover_height}" rpy="0 0 0"/>
        </joint>

        <joint name="r_thumb_brake" type="revolute">
            <origin xyz="0.028671040000000005 0.01377578 0.0002947999999999995" rpy="-1.6927426298510666 -0.7759529082385159 1.7440212278644769" />
            <parent link="r_glove_hub" />
            <child link="r_thumb_brake" />
            <axis xyz="-1.034557180062956e-07 -2.4449215783872713e-07 -1.0000001372639553" />
            <limit lower="-0.174533" upper="1.047198" effort="100" velocity="1000" />
        </joint>

        <joint name="r_thumb_mcp" type="revolute">
            <origin xyz="0.00530330777216646 0.005303298545576421 0.006999996433025211" rpy="3.0543261909900767 -0.08726646259971639 -2.3542882145657518" />
            <parent link="r_thumb_brake" />
            <child link="r_thumb_flexion_one" />
            <axis xyz="-0.0018989999999999545 0.9962070000000028 0.08699000000000176" />
            <limit lower="-0.174533" upper="0.610865" effort="100" velocity="1000" />
        </joint>

        <joint name="r_thumb_pip" type="revolute">
            <origin xyz="-0.03984770999999979 0.00022789000000000782 -0.003479610000000002" rpy="-3.7025504190272574e-17 -6.733051085556857e-31 -4.163336342348644e-17" />
            <parent link="r_thumb_flexion_one" />
            <child link="r_thumb_flexion_two" />
            <axis xyz="-0.0018990000000058964 0.9962069999997494 0.08698999999936513" />
            <limit lower="0.0" upper="0.872665" effort="100" velocity="1000" />
        </joint>

        <joint name="r_thumb_dip" type="revolute">
            <origin xyz="-0.039847719999877115 0.00022787999999702825 -0.003479599999990739" rpy="2.0111950299604782e-17 -1.3010426069826712e-18 4.597425888860514e-29" />
            <parent link="r_thumb_flexion_two" />
            <child link="r_thumb_flexion_three" />
            <axis xyz="-0.00189899999999976 0.996206999999922 0.0869899999999425" />
            <limit lower="-0.174533" upper="1.570796" effort="100" velocity="1000" />
        </joint>

        <joint name="r_index_brake" type="revolute">
            <origin xyz="0.025 0.1015 0.025001100000000002" rpy="-1.9721522630525295e-31 6.360609357992649e-31 3.944304526105059e-31" />
            <parent link="r_glove_hub" />
            <child link="r_index_brake" />
            <axis xyz="-1.6006881522617508e-31 0.0 1.0" />
            <limit lower="-0.349066" upper="0.349066" effort="100" velocity="1000" />
        </joint>

        <joint name="r_index_mcp" type="revolute">
            <origin xyz="0.0 0.0125 0.005" rpy="1.5707963267948994 6.902532920683812e-31 -1.5707963267948968" />
            <parent link="r_index_brake" />
            <child link="r_index_flexion_one" />
            <axis xyz="2.2204460492503284e-16 3.9671451829137585e-31 1.000000000000003" />
            <limit lower="-0.523599" upper="1.570796" effort="100" velocity="1000" />
        </joint>

        <joint name="r_index_pip" type="revolute">
            <origin xyz="-0.03999999999999977 0.0 1.3322676295501878e-17" rpy="-3.141592653589793 2.2204460492503294e-16 4.410505659055223e-31" />
            <parent link="r_index_flexion_one" />
            <child link="r_index_flexion_two" />
            <axis xyz="-7.888609052210136e-31 5.00181505440204e-32 -1.0000000000000016" />
            <limit lower="0.0" upper="1.745329" effort="100" velocity="1000" />
        </joint>

        <joint name="r_index_dip" type="revolute">
            <origin xyz="-0.02999999999999986 0.0 0.0" rpy="-3.141592653589793 1.1832913578315179e-30 3.9443045261050244e-31" />
            <parent link="r_index_flexion_two" />
            <child link="r_index_flexion_three" />
            <axis xyz="3.944304526105059e-31 -3.7336409773599426e-32 1.000000000000001" />
            <limit lower="-0.087266" upper="1.570796" effort="100" velocity="1000" />
        </joint>

        <joint name="r_middle_brake" type="revolute">
            <origin xyz="0.045 0.1015 0.025" rpy="-1.9721522630525295e-31 6.360609357992649e-31 3.944304526105059e-31" />
            <parent link="r_glove_hub" />
            <child link="r_middle_brake" />
            <axis xyz="-1.6006881522617508e-31 0.0 1.0" />
            <limit lower="-0.349066" upper="0.349066" effort="100" velocity="1000" />
        </joint>

        <joint name="r_middle_mcp" type="revolute">
            <origin xyz="0.0 0.0125 0.005" rpy="1.5707963267948994 3.944304526105037e-31 -1.5707963267948968" />
            <parent link="r_middle_brake" />
            <child link="r_middle_flexion_one" />
            <axis xyz="2.220446049250329e-16 -2.743656440857823e-31 1.0000000000000013" />
            <limit lower="-0.523599" upper="1.570796" effort="100" velocity="1000" />
        </joint>

        <joint name="r_middle_pip" type="revolute">
            <origin xyz="-0.044999999999999755 0.0 8.881784197001253e-18" rpy="-3.4093030523414468e-31 2.2204460492503264e-16 -1.7903995299227937e-30" />
            <parent link="r_middle_flexion_one" />
            <child link="r_middle_flexion_two" />
            <axis xyz="-2.4651903288156498e-32 2.1054281083331788e-31 0.9999999999999951" />
            <limit lower="0.0" upper="1.745329" effort="100" velocity="1000" />
        </joint>

        <joint name="r_middle_dip" type="revolute">
            <origin xyz="-0.030000000000000124 0.0 0.0" rpy="-1.8733359704785427e-31 -2.218671295934096e-31 4.733165431326106e-30" />
            <parent link="r_middle_flexion_two" />
            <child link="r_middle_flexion_three" />
            <axis xyz="1.9721522630525181e-31 2.3209213785464143e-32 0.9999999999999947" />
            <limit lower="-0.087266" upper="1.570796" effort="100" velocity="1000" />
        </joint>

        <joint name="r_ring_brake" type="revolute">
            <origin xyz="0.0675 0.1015 0.025" rpy="-1.9721522630525295e-31 6.360609357992649e-31 3.944304526105059e-31" />
            <parent link="r_glove_hub" />
            <child link="r_ring_brake" />
            <axis xyz="-1.6006881522617508e-31 0.0 1.0" />
            <limit lower="-0.349066" upper="0.349066" effort="100" velocity="1000" />
        </joint>

        <joint name="r_ring_mcp" type="revolute">
            <origin xyz="0.0 0.0075 0.005" rpy="1.5707963267948994 2.3665827156630218e-30 -1.570796326794897" />
            <parent link="r_ring_brake" />
            <child link="r_ring_flexion_one" />
            <axis xyz="4.440892098500658e-16 -1.9126221254689664e-31 1.0000000000000022" />
            <limit lower="-0.523599" upper="1.570796" effort="100" velocity="1000" />
        </joint>

        <joint name="r_ring_pip" type="revolute">
            <origin xyz="-0.039999999999999696 -4.440892098500626e-18 1.7763568394002505e-17" rpy="-1.0521954611961268e-30 4.440892098500648e-16 -2.0031744114551858e-30" />
            <parent link="r_ring_flexion_one" />
            <child link="r_ring_flexion_two" />
            <axis xyz="9.385156069474515e-62 -6.016631591149275e-32 0.9999999999999936" />
            <limit lower="0.0" upper="1.745329" effort="100" velocity="1000" />
        </joint>

        <joint name="r_ring_dip" type="revolute">
            <origin xyz="-0.03 0.0 0.0" rpy="8.661648108030636e-31 -2.8941170293315487e-60 6.310887241768106e-30" />
            <parent link="r_ring_flexion_two" />
            <child link="r_ring_flexion_three" />
            <axis xyz="2.6082657545562474e-60 8.059984948915678e-31 0.9999999999999964" />
            <limit lower="-0.087266" upper="1.570796" effort="100" velocity="1000" />
        </joint>

        <joint name="r_pinky_brake" type="revolute">
            <origin xyz="0.085 0.09150000000000001 0.025" rpy="-1.9721522630525295e-31 6.360609357992649e-31 3.944304526105059e-31" />
            <parent link="r_glove_hub" />
            <child link="r_pinky_brake" />
            <axis xyz="-1.6006881522617508e-31 0.0 1.0" />
            <limit lower="-0.349066" upper="0.349066" effort="100" velocity="1000" />
        </joint>

        <joint name="r_pinky_mcp" type="revolute">
            <origin xyz="0.0 0.0075 0.0030000000000000027" rpy="-1.5707963267948941 3.9443045261050205e-31 -1.5707963267948966" />
            <parent link="r_pinky_brake" />
            <child link="r_pinky_flexion_one" />
            <axis xyz="1.4412647038179638e-61 5.1214800739245165e-31 -1.0000000000000044" />
            <limit lower="-0.523599" upper="1.570796" effort="100" velocity="1000" />
        </joint>

        <joint name="r_pinky_pip" type="revolute">
            <origin xyz="-0.03499999999999966 4.440892098500626e-18 1.7763568394002505e-17" rpy="5.273690307704786e-31 -3.174759783138916e-60 5.9164567891575955e-30" />
            <parent link="r_pinky_flexion_one" />
            <child link="r_pinky_flexion_two" />
            <axis xyz="-5.317573665292917e-64 -1.5221023378027343e-32 -1.000000000000001" />
            <limit lower="0.0" upper="1.745329" effort="100" velocity="1000" />
        </joint>

        <joint name="r_pinky_dip" type="revolute">
            <origin xyz="-0.014999999999999859 0.0 1.7763568394002505e-17" rpy="1.3440221301716692e-31 -1.972152263052545e-31 -6.3108872417680916e-30" />
            <parent link="r_pinky_flexion_two" />
            <child link="r_pinky_flexion_three" />
            <axis xyz="-1.972152263052542e-31 -1.4962323639519502e-31 -1.000000000000005" />
            <limit lower="-0.087266" upper="1.570796" effort="100" velocity="1000" />
        </joint>

        <joint name="r_thumper" type="revolute">
            <origin xyz="0.05 0.0385 0.025" rpy="-1.9721522630525295e-31 6.360609357992649e-31 3.944304526105059e-31" />
            <parent link="r_glove_hub" />
            <child link="r_thumper" />
            <axis xyz="-1.6006881522617508e-31 0.0 1.0" />
            <limit lower="0.0" upper="1.745329" effort="100" velocity="1000" />
        </joint>

    </xacro:macro>
</robot>